<mujoco model="ant6">
  <compiler inertiafromgeom="true" angle="degree" coordinate="local" />


  <option timestep="0.02" integrator="RK4" />


  <custom>
    <numeric name="init_qpos" data="0.0 0.0 0.55 1.0 0.0 0.0 0.0 0.0 1.0 0.0 -1.0 0.0 -1.0 0.0 1.0" />
  </custom>


  <default>
    <joint limited="true" armature="1" damping="1" />
    <geom condim="3" conaffinity="0" margin="0.01" friction="1 0.5 0.5" solref=".02 1" solimp=".8 .8 .01" rgba="0.8 0.6 0.4 1" density="5.0" />
  </default>


  <!-- /-->
  <!-- World and Body /-->
  <worldbody>


    <!-- Body: Animal called "torso"/-->
    <body name="torso" pos="0 0 0.75">
      <!-- Middle part of the body /-->
      <!--geom name="torso_geom" type="sphere" size="0.025" pos="0 0 0" /--> <!-- Original body /-->
      <geom name="torso_geom" type="capsule" size="0.1" fromto="0.0 -0.25 0.0 0.0 0.25 0.0" pos="0 0 0" />
      <!-- Head /-->
      <geom name="direction" type="sphere" size="0.15" pos="0.0 0.35 0.07" density="0.1"/><!--this is for direction-->
      <!-- Tail of the body /-->
      <geom name="tail" type="sphere" size="0.2" pos="0.0 -0.4 0.0" />

      <!--joint name="root" type="free" limited="false" pos="0 0 0" axis="0 0 1" margin="0.01" armature="0" damping="0" /-->

      <body name="front_right_leg" pos="0.02 0.05 0"> <!-- Reference zero-coordinates: body pos in line 37 /-->
        <geom name="aux_1_geom" type="capsule" size="0.06" fromto="0.0 0.0 0.0 0.2 0.2 0.0" />
        <body name="aux_1" pos="0.2 0.2 0"> <!-- Reference zero-coordinates: body pos in line 49 /-->
          <joint name="hip_1" type="hinge" pos="0.0 0.0 0.0" axis="0 0 1" range="-30 30" />
          <geom name="front_right_leg_geom" type="capsule" size="0.04" fromto="0.0 0.0 0.0 0.2 0.2 0.0" />
          <body pos="0.2 0.2 0">  <!-- Reference zero-coordinates: body pos in line 51 /-->
            <joint name="ankle_1" type="hinge" pos="0.0 0.0 0.0" axis="-1 1 0" range="30 70" />
            <geom name="front_right_ankle_geom" type="capsule" size="0.06" fromto="0.0 0.0 0.0 0.4 0.4 0.0" />
          </body>
        </body>
      </body>

      <body name="front_left_leg" pos="-0.02 0.05 0">
        <geom name="aux_2_geom" type="capsule" size="0.06" fromto="0.0 0.0 0.0 -0.2 0.2 0.0" />
        <body name="aux_2" pos="-0.2 0.2 0">
          <joint name="hip_2" type="hinge" pos="0.0 0.0 0.0" axis="0 0 1" range="-30 30" />
          <geom name="front_left_leg_geom" type="capsule" size="0.04" fromto="0.0 0.0 0.0 -0.2 0.2 0.0" />
          <body pos="-0.2 0.2 0">
            <joint name="ankle_2" type="hinge" pos="0.0 0.0 0.0" axis="1 1 0" range="-70 -30" />
            <geom name="front_left_ankle_geom" type="capsule" size="0.06" fromto="0.0 0.0 0.0 -0.4 0.4 0.0" />
          </body>
        </body>
      </body>

      <body name="middle_right_leg" pos="0.02 0 0">
        <geom name="aux_5_geom" type="capsule" size="0.06" fromto="0.0 0.0 0.0 0.3 0.0 0.0" />
        <body name="aux_5" pos="0.3 0.0 0">
          <joint name="hip_5" type="hinge" pos="0.0 0.0 0.0" axis="0 0 1" range="-30 30" />
          <geom name="mid_right_leg_geom" type="capsule" size="0.04" fromto="0.0 0.0 0.0 0.3 0.0 0.0" />
          <body pos="0.3 0.0 0">
            <joint name="ankle_5" type="hinge" pos="0.0 0.0 0.0" axis="-1 1 0" range="30 70" />
            <geom name="mid_right_ankle_geom" type="capsule" size="0.06" fromto="0.0 0.0 0.0 0.565685 0.0 0.0" />
          </body>
        </body>
      </body>

      <body name="middle_left_leg" pos="-0.02 0 0">
        <geom name="aux_6_geom" type="capsule" size="0.06" fromto="0.0 0.0 0.0 -0.3 0.0 0.0" />
        <body name="aux_6" pos="-0.3 0.0 0">
          <joint name="hip_6" type="hinge" pos="0.0 0.0 0.0" axis="0 0 1" range="-30 30" />
          <geom name="mid_left_leg_geom" type="capsule" size="0.04" fromto="0.0 0.0 0.0 -0.3 0.0 0.0" />
          <body pos="-0.3 0.0 0">
            <joint name="ankle_6" type="hinge" pos="0.0 0.0 0.0" axis="1 1 0" range="-70 -30" />
            <geom name="mid_left_ankle_geom" type="capsule" size="0.06" fromto="0.0 0.0 0.0 -0.565685 0.0 0.0" />
          </body>
        </body>
      </body>

      <body name="back_right_leg" pos="0.02 -0.05 0">
        <geom name="aux_3_geom" type="capsule" size="0.06" fromto="0.0 0.0 0.0 -0.2 -0.2 0.0" />
        <body name="aux_3" pos="-0.2 -0.2 0">
          <joint name="hip_3" type="hinge" pos="0.0 0.0 0.0" axis="0 0 1" range="-30 30" />
          <geom name="back_right_leg_geom" type="capsule" size="0.04" fromto="0.0 0.0 0.0 -0.2 -0.2 0.0" />
          <body pos="-0.2 -0.2 0">
            <joint name="ankle_3" type="hinge" pos="0.0 0.0 0.0" axis="-1 1 0" range="-70 -30" />
            <geom name="back_right_ankle_geom" type="capsule" size="0.06" fromto="0.0 0.0 0.0 -0.4 -0.4 0.0" />
          </body>
        </body>
      </body>

      <body name="back_left_leg" pos="-0.02 -0.05 0">
        <geom name="aux_4_geom" type="capsule" size="0.06" fromto="0.0 0.0 0.0 0.2 -0.2 0.0" />
        <body name="aux_4" pos="0.2 -0.2 0">
          <joint name="hip_4" type="hinge" pos="0.0 0.0 0.0" axis="0 0 1" range="-30 30" />
          <geom name="back_left_leg_geom" type="capsule" size="0.04" fromto="0.0 0.0 0.0 0.2 -0.2 0.0" />
          <body pos="0.2 -0.2 0">
            <joint name="ankle_4" type="hinge" pos="0.0 0.0 0.0" axis="1 1 0" range="30 70" />
            <geom name="back_left_ankle_geom" type="capsule" size="0.06" fromto="0.0 0.0 0.0 0.4 -0.4 0.0" />
          </body>
        </body>
      </body>

    </body> <!-- of "torso"/-->
  </worldbody>


  <actuator>
    <motor joint="hip_4"   ctrlrange="-150.0 150.0" ctrllimited="true" />
    <motor joint="ankle_4" ctrlrange="-150.0 150.0" ctrllimited="true" />
    <motor joint="hip_1"   ctrlrange="-150.0 150.0" ctrllimited="true" />
    <motor joint="ankle_1" ctrlrange="-150.0 150.0" ctrllimited="true" />
    <motor joint="hip_2"   ctrlrange="-150.0 150.0" ctrllimited="true" />
    <motor joint="ankle_2" ctrlrange="-150.0 150.0" ctrllimited="true" />
    <motor joint="hip_3"   ctrlrange="-150.0 150.0" ctrllimited="true" />
    <motor joint="ankle_3" ctrlrange="-150.0 150.0" ctrllimited="true" />
    <motor joint="hip_5"   ctrlrange="-150.0 150.0" ctrllimited="true" />
    <motor joint="ankle_5" ctrlrange="-150.0 150.0" ctrllimited="true" />
    <motor joint="hip_6"   ctrlrange="-150.0 150.0" ctrllimited="true" />
    <motor joint="ankle_6" ctrlrange="-150.0 150.0" ctrllimited="true" />
  </actuator>
</mujoco>
